<?xml version="1.0" ?>
<robot name="my_robot">
    <material name="red">
        <color rgba="1.0 0.0 0.0 1.0" />
    </material>
    n
    <material name="green">
        <color rgba="0.0 1.0 0.0 1.0" />
    </material>
    <material name="blue">
        <color rgba="0.0 0.0 1.0 1.0" />
    </material>
    <material name="dark">
        <color rgba="0.4 0.4 0.4 1.0" />
    </material>
    <material name="light">
        <color rgba="0.6 0.6 0.6 1.0" />
    </material>
    <link name="base_link">
        <visual>
            <geometry>
                <cylinder length="0.05" radius="0.1" />
            </geometry>
            <origin rpy="0 0 0" xyz="0 0 -0.025" />
            <material name="dark" />
        </visual>
    </link>
    <link name="link1">
        <visual>
            <geometry>
                <box size="0.1 0.1 0.1" />
            </geometry>
            <origin rpy="0 0 0" xyz="0 0 0.05" />
            <material name="light" />
        </visual>
    </link>
    <link name="link2">
        <visual>
            <geometry>
                <box size="0.55 0.05 0.05" />
            </geometry>
            <origin rpy="0 0 0" xyz="0.25 0 0.075" />
            <material name="dark" />
        </visual>
    </link>
    <link name="link3">
        <visual>
            <geometry>
                <box size="0.55 0.05 0.05" />
            </geometry>
            <origin rpy="0 0 0" xyz="0.25 0 0.025" />
            <material name="light" />
        </visual>
    </link>
    <link name="link4">
        <visual>
            <geometry>
                <box size="0.05 0.05 0.05" />
            </geometry>
            <origin rpy="0 0 0" xyz="0 0 0.075" />
            <material name="dark" />
        </visual>
    </link>
    <link name="link5">
        <visual>
            <geometry>
                <box size="0.05 0.05 0.05" />
            </geometry>
            <origin rpy="0 0 0" xyz="0 0 0.05" />
            <material name="light" />
        </visual>
    </link>
    <link name="link6">
        <visual>
            <geometry>
                <cylinder length="0.025" radius="0.025" />
            </geometry>
            <origin rpy="0 0 0" xyz="0 0 -0.0125" />
            <material name="red" />
        </visual>
    </link>
    <joint name="joint1" type="revolute">
        <parent link="base_link" />
        <child link="link1" />
        <origin rpy="0 0 0" xyz="0 0 0" />
        <axis xyz="0 0 1" />
        <limit lower="-6.28" upper="6.28" velocity="1.0" effort="1000.0" />
    </joint>
    <joint name="joint2" type="revolute">
        <parent link="link1" />
        <child link="link2" />
        <origin rpy="0 -1.57 0" xyz="0 0 0.05" />
        <axis xyz="0 0 1" />
        <limit lower="-6.28" upper="6.28" velocity="1.0" effort="1000.0" />
    </joint>
    <joint name="joint3" type="revolute">
        <parent link="link2" />
        <child link="link3" />
        <origin rpy="0 0 0" xyz="0.5 0 0" />
        <axis xyz="0 0 1" />
        <limit lower="-6.28" upper="6.28" velocity="1.0" effort="1000.0" />
    </joint>
    <joint name="joint4" type="revolute">
        <parent link="link3" />
        <child link="link4" />
        <origin rpy="0 0 0" xyz="0.5 0 0" />
        <axis xyz="0 0 1" />
        <limit lower="-6.28" upper="6.28" velocity="1.0" effort="1000.0" />
    </joint>
    <joint name="joint5" type="revolute">
        <parent link="link4" />
        <child link="link5" />
        <origin rpy="0 1.57 0" xyz="0 0 0.075" />
        <axis xyz="0 0 1" />
        <limit lower="-6.28" upper="6.28" velocity="1.0" effort="1000.0" />
    </joint>
    <joint name="joint6" type="revolute">
        <parent link="link5" />
        <child link="link6" />
        <origin rpy="0 -1.57 0" xyz="-0.0375 0 0.05" />
        <axis xyz="0 0 1" />
        <limit lower="-6.28" upper="6.28" velocity="1.0" effort="1000.0" />
    </joint>
    
<transmission name="trans_joint1">
        <type>transmission_interface/SimpleTransmission</type>
        <joint name="joint1">
            <hardwareInterface>hardware_interface/EffortJointInterface</hardwareInterface>
        </joint>
        <actuator name="joint1_motor">
            <hardwareInterface>hardware_interface/EffortJointInterface</hardwareInterface>
            <mechanicalReduction>1</mechanicalReduction>
        </actuator>
    </transmission>
    <transmission name="trans_joint2">
        <type>transmission_interface/SimpleTransmission</type>
        <joint name="joint2">
            <hardwareInterface>hardware_interface/EffortJointInterface</hardwareInterface>
        </joint>
        <actuator name="joint2_motor">
            <hardwareInterface>hardware_interface/EffortJointInterface</hardwareInterface>
            <mechanicalReduction>1</mechanicalReduction>
        </actuator>
    </transmission>
    <transmission name="trans_joint3">
        <type>transmission_interface/SimpleTransmission</type>
        <joint name="joint3">
            <hardwareInterface>hardware_interface/EffortJointInterface</hardwareInterface>
        </joint>
        <actuator name="joint3_motor">
            <hardwareInterface>hardware_interface/EffortJointInterface</hardwareInterface>
            <mechanicalReduction>1</mechanicalReduction>
        </actuator>
    </transmission>
    <transmission name="trans_joint4">
        <type>transmission_interface/SimpleTransmission</type>
        <joint name="joint4">
            <hardwareInterface>hardware_interface/EffortJointInterface</hardwareInterface>
        </joint>
        <actuator name="joint4_motor">
            <hardwareInterface>hardware_interface/EffortJointInterface</hardwareInterface>
            <mechanicalReduction>1</mechanicalReduction>
        </actuator>
    </transmission>
    <transmission name="trans_joint5">
        <type>transmission_interface/SimpleTransmission</type>
        <joint name="joint5">
            <hardwareInterface>hardware_interface/EffortJointInterface</hardwareInterface>
        </joint>
        <actuator name="joint5_motor">
            <hardwareInterface>hardware_interface/EffortJointInterface</hardwareInterface>
            <mechanicalReduction>1</mechanicalReduction>
        </actuator>
    </transmission>
    <transmission name="trans_joint6">
        <type>transmission_interface/SimpleTransmission</type>
        <joint name="joint6">
            <hardwareInterface>hardware_interface/EffortJointInterface</hardwareInterface>
        </joint>
        <actuator name="joint6_motor">
            <hardwareInterface>hardware_interface/EffortJointInterface</hardwareInterface>
            <mechanicalReduction>1</mechanicalReduction>
        </actuator>
    </transmission>
    <gazebo>
        <plugin name="gazebo_ros_control" filename="libgazebo_ros_control.so">
            <robotNamespace>/</robotNamespace>
        </plugin>
    </gazebo>
</robot>
